[2022-03-16 12:23:41,960] {taskinstance.py:1037} INFO - Dependencies all met for <TaskInstance: Assignment.Write_into_csv scheduled__2022-03-14T06:00:00+00:00 [queued]>
[2022-03-16 12:23:42,025] {taskinstance.py:1037} INFO - Dependencies all met for <TaskInstance: Assignment.Write_into_csv scheduled__2022-03-14T06:00:00+00:00 [queued]>
[2022-03-16 12:23:42,028] {taskinstance.py:1243} INFO - 
--------------------------------------------------------------------------------
[2022-03-16 12:23:42,030] {taskinstance.py:1244} INFO - Starting attempt 2 of 2
[2022-03-16 12:23:42,032] {taskinstance.py:1245} INFO - 
--------------------------------------------------------------------------------
[2022-03-16 12:23:42,170] {taskinstance.py:1264} INFO - Executing <Task(PythonOperator): Write_into_csv> on 2022-03-14 06:00:00+00:00
[2022-03-16 12:23:42,201] {standard_task_runner.py:52} INFO - Started process 1588 to run task
[2022-03-16 12:23:42,237] {standard_task_runner.py:76} INFO - Running: ['***', 'tasks', 'run', 'Assignment', 'Write_into_csv', 'scheduled__2022-03-14T06:00:00+00:00', '--job-id', '7', '--raw', '--subdir', 'DAGS_FOLDER/DAG_file.py', '--cfg-path', '/tmp/tmp4gz1jpif', '--error-file', '/tmp/tmpsuwbf2dx']
[2022-03-16 12:23:42,242] {standard_task_runner.py:77} INFO - Job 7: Subtask Write_into_csv
[2022-03-16 12:23:42,476] {logging_mixin.py:109} INFO - Running <TaskInstance: Assignment.Write_into_csv scheduled__2022-03-14T06:00:00+00:00 [running]> on host e8c8ac0dbee4
[2022-03-16 12:23:42,788] {taskinstance.py:1431} INFO - Exporting the following env vars:
AIRFLOW_CTX_DAG_EMAIL=***@***.com
AIRFLOW_CTX_DAG_OWNER=Airflow
AIRFLOW_CTX_DAG_ID=Assignment
AIRFLOW_CTX_TASK_ID=Write_into_csv
AIRFLOW_CTX_EXECUTION_DATE=2022-03-14T06:00:00+00:00
AIRFLOW_CTX_DAG_RUN_ID=scheduled__2022-03-14T06:00:00+00:00
[2022-03-16 12:23:44,298] {logging_mixin.py:109} INFO - {'message': 'Too many requests'}
[2022-03-16 12:23:44,316] {taskinstance.py:1718} ERROR - Task failed with exception
Traceback (most recent call last):
  File "/home/airflow/.local/lib/python3.7/site-packages/airflow/models/taskinstance.py", line 1334, in _run_raw_task
    self._execute_task_with_callbacks(context)
  File "/home/airflow/.local/lib/python3.7/site-packages/airflow/models/taskinstance.py", line 1460, in _execute_task_with_callbacks
    result = self._execute_task(context, self.task)
  File "/home/airflow/.local/lib/python3.7/site-packages/airflow/models/taskinstance.py", line 1516, in _execute_task
    result = execute_callable(context=context)
  File "/home/airflow/.local/lib/python3.7/site-packages/airflow/operators/python.py", line 174, in execute
    return_value = self.execute_callable()
  File "/home/airflow/.local/lib/python3.7/site-packages/airflow/operators/python.py", line 188, in execute_callable
    return self.python_callable(*self.op_args, **self.op_kwargs)
  File "/opt/airflow/dags/current_wheather_data.py", line 24, in write_csv
    list_item = [data["name"],data["weather"][0]["description"],data["main"]["temp"], data["main"]["feels_like"],
KeyError: 'name'
[2022-03-16 12:23:44,901] {taskinstance.py:1282} INFO - Marking task as FAILED. dag_id=Assignment, task_id=Write_into_csv, execution_date=20220314T060000, start_date=20220316T122341, end_date=20220316T122344
[2022-03-16 12:23:45,044] {standard_task_runner.py:92} ERROR - Failed to execute job 7 for task Write_into_csv
Traceback (most recent call last):
  File "/home/airflow/.local/lib/python3.7/site-packages/airflow/task/task_runner/standard_task_runner.py", line 85, in _start_by_fork
    args.func(args, dag=self.dag)
  File "/home/airflow/.local/lib/python3.7/site-packages/airflow/cli/cli_parser.py", line 48, in command
    return func(*args, **kwargs)
  File "/home/airflow/.local/lib/python3.7/site-packages/airflow/utils/cli.py", line 92, in wrapper
    return f(*args, **kwargs)
  File "/home/airflow/.local/lib/python3.7/site-packages/airflow/cli/commands/task_command.py", line 298, in task_run
    _run_task_by_selected_method(args, dag, ti)
  File "/home/airflow/.local/lib/python3.7/site-packages/airflow/cli/commands/task_command.py", line 107, in _run_task_by_selected_method
    _run_raw_task(args, ti)
  File "/home/airflow/.local/lib/python3.7/site-packages/airflow/cli/commands/task_command.py", line 184, in _run_raw_task
    error_file=args.error_file,
  File "/home/airflow/.local/lib/python3.7/site-packages/airflow/utils/session.py", line 70, in wrapper
    return func(*args, session=session, **kwargs)
  File "/home/airflow/.local/lib/python3.7/site-packages/airflow/models/taskinstance.py", line 1334, in _run_raw_task
    self._execute_task_with_callbacks(context)
  File "/home/airflow/.local/lib/python3.7/site-packages/airflow/models/taskinstance.py", line 1460, in _execute_task_with_callbacks
    result = self._execute_task(context, self.task)
  File "/home/airflow/.local/lib/python3.7/site-packages/airflow/models/taskinstance.py", line 1516, in _execute_task
    result = execute_callable(context=context)
  File "/home/airflow/.local/lib/python3.7/site-packages/airflow/operators/python.py", line 174, in execute
    return_value = self.execute_callable()
  File "/home/airflow/.local/lib/python3.7/site-packages/airflow/operators/python.py", line 188, in execute_callable
    return self.python_callable(*self.op_args, **self.op_kwargs)
  File "/opt/airflow/dags/current_wheather_data.py", line 24, in write_csv
    list_item = [data["name"],data["weather"][0]["description"],data["main"]["temp"], data["main"]["feels_like"],
KeyError: 'name'
[2022-03-16 12:23:45,120] {local_task_job.py:154} INFO - Task exited with return code 1
[2022-03-16 12:23:45,968] {local_task_job.py:264} INFO - 0 downstream tasks scheduled from follow-on schedule check
